---
layout: post
title: "Better Python: Error Handling Done Right"
date: 2025-02-12
summary: "Master Python's exception handling to build robust applications that fail gracefully and provide meaningful feedback to users and developers."
categories: python programming error-handling exceptions better-python
---

# Graceful Failure: The Art of Error Handling

Error handling is where good code becomes great code. It's the difference between an application that crashes mysteriously and one that fails gracefully, providing clear feedback and recovery options. Python's exception system is powerful and flexibleâ€”let's learn to use it effectively.

## The Philosophy of Exception Handling

Python follows the "Easier to Ask for Forgiveness than Permission" (EAFP) principle, which encourages using exceptions for control flow rather than extensive precondition checking.

```python
# LBYL (Look Before You Leap) - Not Pythonic
def get_value_lbyl(dictionary, key):
    if key in dictionary:
        if isinstance(dictionary[key], str):
            if len(dictionary[key]) > 0:
                return dictionary[key].upper()
    return None

# EAFP (Easier to Ask for Forgiveness than Permission) - Pythonic
def get_value_eafp(dictionary, key):
    try:
        return dictionary[key].upper()
    except (KeyError, AttributeError):
        return None
```

## Exception Hierarchy and Built-in Exceptions

Understanding Python's exception hierarchy helps you catch the right exceptions:

```python
# Exception hierarchy (simplified)
BaseException
 +-- SystemExit
 +-- KeyboardInterrupt
 +-- GeneratorExit
 +-- Exception
      +-- StopIteration
      +-- ArithmeticError
      |    +-- ZeroDivisionError
      |    +-- OverflowError
      +-- LookupError
      |    +-- IndexError
      |    +-- KeyError
      +-- OSError
      |    +-- FileNotFoundError
      |    +-- PermissionError
      +-- ValueError
      +-- TypeError
      +-- RuntimeError
```

### Catching Specific Exceptions

```python
def safe_division(a, b):
    try:
        result = a / b
        return result
    except ZeroDivisionError:
        print("Cannot divide by zero!")
        return None
    except TypeError:
        print("Both arguments must be numbers!")
        return None

# Multiple exceptions
def process_data(data):
    try:
        return data['value'] * 2
    except (KeyError, TypeError) as e:
        print(f"Data processing error: {e}")
        return 0
```

## The Complete Exception Handling Pattern

### try, except, else, finally

```python
def read_config_file(filename):
    """Demonstrate complete exception handling pattern."""
    config = None
    file_handle = None
    
    try:
        print(f"Attempting to read {filename}")
        file_handle = open(filename, 'r')
        config_text = file_handle.read()
        config = json.loads(config_text)
        
    except FileNotFoundError:
        print(f"Config file {filename} not found. Using defaults.")
        config = get_default_config()
        
    except PermissionError:
        print(f"Permission denied reading {filename}")
        raise  # Re-raise the exception
        
    except json.JSONDecodeError as e:
        print(f"Invalid JSON in {filename}: {e}")
        config = get_default_config()
        
    except Exception as e:
        print(f"Unexpected error reading config: {e}")
        raise
        
    else:
        # Executes only if no exception occurred
        print("Config file loaded successfully")
        validate_config(config)
        
    finally:
        # Always executes, even if there's an exception
        if file_handle:
            file_handle.close()
            print("File handle closed")
    
    return config
```

## Custom Exceptions

Creating your own exceptions makes error handling more precise and meaningful:

```python
# Base exception for your application
class AppError(Exception):
    """Base exception for application errors."""
    pass

class ValidationError(AppError):
    """Raised when data validation fails."""
    def __init__(self, field, value, message="Validation failed"):
        self.field = field
        self.value = value
        self.message = message
        super().__init__(f"{field}: {message} (got {value})")

class NetworkError(AppError):
    """Raised when network operations fail."""
    def __init__(self, url, status_code=None, message="Network request failed"):
        self.url = url
        self.status_code = status_code
        self.message = message
        super().__init__(f"Network error for {url}: {message}")

class ConfigurationError(AppError):
    """Raised when configuration is invalid."""
    pass

# Usage examples
def validate_email(email):
    if '@' not in email:
        raise ValidationError('email', email, 'Must contain @ symbol')
    
    if len(email) < 5:
        raise ValidationError('email', email, 'Must be at least 5 characters')

def fetch_data(url):
    try:
        response = requests.get(url)
        response.raise_for_status()
        return response.json()
    except requests.RequestException as e:
        raise NetworkError(url, getattr(e.response, 'status_code', None)) from e
```

## Exception Chaining and Context

Python provides mechanisms to preserve error context:

```python
def process_user_data(user_id):
    try:
        user_data = fetch_user_from_database(user_id)
    except DatabaseConnectionError as e:
        # Chain exceptions to preserve context
        raise ProcessingError(f"Failed to process user {user_id}") from e

def alternative_chaining(user_id):
    try:
        user_data = fetch_user_from_database(user_id)
    except DatabaseConnectionError:
        # Suppress the original exception context
        raise ProcessingError(f"Failed to process user {user_id}") from None

# Implicit chaining happens automatically
def implicit_chaining():
    try:
        risky_operation()
    except ValueError:
        # If another exception occurs here, it's automatically chained
        another_risky_operation()
```

## Logging and Exception Handling

Proper logging is crucial for debugging and monitoring:

```python
import logging
import traceback

# Configure logging
logging.basicConfig(
    level=logging.INFO,
    format='%(asctime)s - %(name)s - %(levelname)s - %(message)s'
)
logger = logging.getLogger(__name__)

def robust_operation(data):
    try:
        result = complex_processing(data)
        logger.info(f"Successfully processed {len(data)} items")
        return result
        
    except ValidationError as e:
        # Log validation errors at WARNING level
        logger.warning(f"Validation failed: {e}")
        return None
        
    except NetworkError as e:
        # Log network errors with more detail
        logger.error(f"Network operation failed: {e.url} (status: {e.status_code})")
        # Could implement retry logic here
        raise
        
    except Exception as e:
        # Log unexpected errors with full traceback
        logger.error(f"Unexpected error in robust_operation: {e}")
        logger.debug(traceback.format_exc())  # Full traceback in debug
        raise

# Context manager for exception logging
from contextlib import contextmanager

@contextmanager
def log_exceptions(operation_name):
    try:
        yield
    except Exception as e:
        logger.error(f"Error in {operation_name}: {e}")
        logger.debug(traceback.format_exc())
        raise

# Usage
with log_exceptions("data processing"):
    process_large_dataset(data)
```

## Retry Mechanisms

Implementing intelligent retry logic for transient failures:

```python
import time
import random
from functools import wraps

def retry_with_backoff(
    max_retries=3, 
    backoff_factor=1, 
    exceptions=(Exception,),
    jitter=True
):
    def decorator(func):
        @wraps(func)
        def wrapper(*args, **kwargs):
            last_exception = None
            
            for attempt in range(max_retries + 1):
                try:
                    return func(*args, **kwargs)
                    
                except exceptions as e:
                    last_exception = e
                    
                    if attempt == max_retries:
                        logger.error(f"All {max_retries + 1} attempts failed for {func.__name__}")
                        raise
                    
                    # Calculate backoff time
                    base_delay = backoff_factor * (2 ** attempt)
                    if jitter:
                        delay = base_delay * (0.5 + random.random() * 0.5)
                    else:
                        delay = base_delay
                    
                    logger.warning(
                        f"Attempt {attempt + 1} failed for {func.__name__}: {e}. "
                        f"Retrying in {delay:.2f}s..."
                    )
                    time.sleep(delay)
            
            raise last_exception
        return wrapper
    return decorator

# Usage
@retry_with_backoff(
    max_retries=3, 
    backoff_factor=1, 
    exceptions=(NetworkError, requests.RequestException)
)
def fetch_critical_data(url):
    response = requests.get(url, timeout=5)
    if response.status_code >= 500:
        raise NetworkError(url, response.status_code, "Server error")
    return response.json()
```

## Circuit Breaker Pattern

Protect your application from cascading failures:

```python
import time
from enum import Enum

class CircuitState(Enum):
    CLOSED = "closed"      # Normal operation
    OPEN = "open"          # Failing, reject requests
    HALF_OPEN = "half_open" # Testing if service recovered

class CircuitBreaker:
    def __init__(self, failure_threshold=5, timeout=60, recovery_timeout=30):
        self.failure_threshold = failure_threshold
        self.timeout = timeout
        self.recovery_timeout = recovery_timeout
        
        self.failure_count = 0
        self.last_failure_time = None
        self.state = CircuitState.CLOSED
        
    def call(self, func, *args, **kwargs):
        if self.state == CircuitState.OPEN:
            if time.time() - self.last_failure_time > self.recovery_timeout:
                self.state = CircuitState.HALF_OPEN
                logger.info("Circuit breaker transitioning to HALF_OPEN")
            else:
                raise CircuitBreakerOpenError("Circuit breaker is OPEN")
        
        try:
            result = func(*args, **kwargs)
            self._on_success()
            return result
            
        except Exception as e:
            self._on_failure()
            raise
    
    def _on_success(self):
        self.failure_count = 0
        if self.state == CircuitState.HALF_OPEN:
            self.state = CircuitState.CLOSED
            logger.info("Circuit breaker CLOSED - service recovered")
    
    def _on_failure(self):
        self.failure_count += 1
        self.last_failure_time = time.time()
        
        if self.failure_count >= self.failure_threshold:
            self.state = CircuitState.OPEN
            logger.warning(f"Circuit breaker OPEN - {self.failure_count} failures")

class CircuitBreakerOpenError(Exception):
    pass

# Usage
api_circuit_breaker = CircuitBreaker(failure_threshold=3, recovery_timeout=30)

def protected_api_call(endpoint):
    return api_circuit_breaker.call(requests.get, endpoint, timeout=5)
```

## Input Validation and Sanitization

Validate input early and provide clear error messages:

```python
from typing import Any, Dict, List, Union
import re

class ValidationError(Exception):
    def __init__(self, field: str, message: str, value: Any = None):
        self.field = field
        self.message = message
        self.value = value
        super().__init__(f"{field}: {message}")

class Validator:
    @staticmethod
    def required(value: Any, field_name: str) -> Any:
        if value is None or value == "":
            raise ValidationError(field_name, "This field is required")
        return value
    
    @staticmethod
    def string_length(value: str, field_name: str, min_len: int = 0, max_len: int = None) -> str:
        if not isinstance(value, str):
            raise ValidationError(field_name, "Must be a string", value)
        
        if len(value) < min_len:
            raise ValidationError(field_name, f"Must be at least {min_len} characters", value)
        
        if max_len and len(value) > max_len:
            raise ValidationError(field_name, f"Must be no more than {max_len} characters", value)
        
        return value
    
    @staticmethod
    def email(value: str, field_name: str) -> str:
        email_pattern = r'^[a-zA-Z0-9._%+-]+@[a-zA-Z0-9.-]+\.[a-zA-Z]{2,}$'
        if not re.match(email_pattern, value):
            raise ValidationError(field_name, "Invalid email format", value)
        return value
    
    @staticmethod
    def numeric_range(value: Union[int, float], field_name: str, min_val: float = None, max_val: float = None) -> Union[int, float]:
        if not isinstance(value, (int, float)):
            raise ValidationError(field_name, "Must be a number", value)
        
        if min_val is not None and value < min_val:
            raise ValidationError(field_name, f"Must be at least {min_val}", value)
        
        if max_val is not None and value > max_val:
            raise ValidationError(field_name, f"Must be no more than {max_val}", value)
        
        return value

def validate_user_data(data: Dict[str, Any]) -> Dict[str, Any]:
    """Validate user registration data."""
    errors = []
    
    try:
        username = Validator.required(data.get('username'), 'username')
        username = Validator.string_length(username, 'username', min_len=3, max_len=20)
    except ValidationError as e:
        errors.append(str(e))
    
    try:
        email = Validator.required(data.get('email'), 'email')
        email = Validator.email(email, 'email')
    except ValidationError as e:
        errors.append(str(e))
    
    try:
        age = data.get('age')
        if age is not None:
            age = Validator.numeric_range(age, 'age', min_val=13, max_val=120)
    except ValidationError as e:
        errors.append(str(e))
    
    if errors:
        raise ValidationError('user_data', '; '.join(errors))
    
    return {
        'username': username,
        'email': email,
        'age': age
    }

# Usage
try:
    user_data = validate_user_data({
        'username': 'jo',  # Too short
        'email': 'invalid-email',  # Invalid format
        'age': 150  # Too high
    })
except ValidationError as e:
    print(f"Validation failed: {e}")
```

## Exception Handling in Async Code

Async functions require special consideration for exception handling:

```python
import asyncio
import aiohttp
from typing import List, Optional

async def fetch_url(session: aiohttp.ClientSession, url: str) -> Optional[dict]:
    try:
        async with session.get(url, timeout=aiohttp.ClientTimeout(total=5)) as response:
            response.raise_for_status()
            return await response.json()
            
    except aiohttp.ClientTimeout:
        logger.warning(f"Timeout fetching {url}")
        return None
        
    except aiohttp.ClientError as e:
        logger.error(f"Client error fetching {url}: {e}")
        return None
        
    except asyncio.CancelledError:
        logger.info(f"Request to {url} was cancelled")
        raise  # Always re-raise CancelledError
        
    except Exception as e:
        logger.error(f"Unexpected error fetching {url}: {e}")
        return None

async def fetch_multiple_urls(urls: List[str]) -> List[dict]:
    async with aiohttp.ClientSession() as session:
        tasks = [fetch_url(session, url) for url in urls]
        
        # Use asyncio.gather with return_exceptions=True to handle partial failures
        results = await asyncio.gather(*tasks, return_exceptions=True)
        
        successful_results = []
        for i, result in enumerate(results):
            if isinstance(result, Exception):
                logger.error(f"Failed to fetch {urls[i]}: {result}")
            elif result is not None:
                successful_results.append(result)
        
        return successful_results
```

## Testing Exception Handling

Make sure your exception handling works correctly:

```python
import pytest
from unittest.mock import patch, Mock

def test_user_validation():
    """Test that validation errors are raised correctly."""
    with pytest.raises(ValidationError) as exc_info:
        validate_user_data({'username': 'jo'})  # Too short
    
    assert 'username' in str(exc_info.value)
    assert 'at least 3 characters' in str(exc_info.value)

def test_retry_mechanism():
    """Test retry decorator with mock failures."""
    call_count = 0
    
    @retry_with_backoff(max_retries=2, backoff_factor=0.1)
    def failing_function():
        nonlocal call_count
        call_count += 1
        if call_count < 3:
            raise NetworkError("http://test.com", 500, "Server error")
        return "success"
    
    result = failing_function()
    assert result == "success"
    assert call_count == 3

def test_circuit_breaker():
    """Test circuit breaker opens after failures."""
    circuit_breaker = CircuitBreaker(failure_threshold=2, recovery_timeout=1)
    
    def failing_function():
        raise NetworkError("http://test.com", 500, "Server error")
    
    # First two failures should work
    for _ in range(2):
        with pytest.raises(NetworkError):
            circuit_breaker.call(failing_function)
    
    # Third call should raise CircuitBreakerOpenError
    with pytest.raises(CircuitBreakerOpenError):
        circuit_breaker.call(failing_function)
```

## Best Practices

### 1. Be Specific with Exception Handling

```python
# Good: Catch specific exceptions
try:
    user_id = int(request.form['user_id'])
    user = User.objects.get(id=user_id)
except ValueError:
    return error_response("Invalid user ID format")
except User.DoesNotExist:
    return error_response("User not found")

# Avoid: Catching everything
try:
    process_user_request(request)
except Exception:  # Too broad
    return error_response("Something went wrong")
```

### 2. Fail Fast, Fail Clearly

```python
def process_payment(amount, currency, payment_method):
    # Validate inputs early
    if amount <= 0:
        raise ValueError("Amount must be positive")
    
    if currency not in SUPPORTED_CURRENCIES:
        raise ValueError(f"Unsupported currency: {currency}")
    
    if not payment_method.is_valid():
        raise PaymentError("Invalid payment method")
    
    # Process payment...
```

### 3. Use Exception Hierarchies

```python
class APIError(Exception):
    """Base class for API errors."""
    pass

class ValidationError(APIError):
    """Input validation failed."""
    pass

class AuthenticationError(APIError):
    """Authentication failed."""
    pass

class RateLimitError(APIError):
    """Rate limit exceeded."""
    pass

# This allows catching related exceptions:
try:
    call_api()
except APIError:  # Catches all API-related errors
    handle_api_error()
```

### 4. Don't Suppress Exceptions Without Good Reason

```python
# Good: Log and re-raise
try:
    critical_operation()
except CriticalError:
    logger.error("Critical operation failed")
    raise  # Don't suppress

# Sometimes acceptable: Known, expected failures
try:
    os.makedirs(directory)
except FileExistsError:
    pass  # Directory already exists, that's fine
```

## Conclusion

Effective error handling is about more than just preventing crashesâ€”it's about building systems that are observable, debuggable, and resilient. Key principles:

- Use specific exceptions rather than broad catches
- Implement proper logging and monitoring
- Design for graceful degradation
- Validate input early and clearly
- Test your error handling paths
- Use exception chaining to preserve context

In our next post, we'll explore type hints and static analysisâ€”tools that help catch errors before they happen.

## Practice Exercises

1. Create a custom exception hierarchy for a web application
2. Implement a decorator that converts exceptions to HTTP responses
3. Build a retry mechanism with exponential backoff and jitter
4. Design a validation system for configuration files

*What's your biggest challenge with error handling? How do you ensure your applications fail gracefully?*